Workbook
Name ACCIONES: '[1]Shares Outstanding'!$C$3:$D$104
Name ACCIONES: '[1]Shares Outstanding'!$C$3:$D$104
Name ACCIONES: '[2]Shares Outstanding'!$C$3:$D$104
Name Debt_Sc: '[2]Tipos de Cambio'!#REF!
Name EERR: '[3]Consolidated Income Statement'!$C$4:$BU$228
Name EERR: '[3]Consolidated Income Statement'!$C$4:$BU$228
Name EERR: '[3]Consolidated Income Statement'!$C$4:$BU$228
Name EERR: '[3]Consolidated Income Statement'!$C$4:$BU$228
Name EERR3: '[1]P&L'!$D$4:$BV$236
Name EERR3: '[1]P&L'!$D$4:$BV$236
Name EERR3: '[2]P&L'!$D$4:$BV$236
Name Periodos: '[1]Tipos de Cambio'!$B$4:$C$82
Name Periodos: '[1]Tipos de Cambio'!$B$4:$C$82
Name Periodos: '[2]Tipos de Cambio'!$B$4:$C$82
Name Sch_Debt: '[2]Tipos de Cambio'!#REF!
Name TC: '[2]Tipos de Cambio'!#REF!
Name TC: '[1]Tipos de Cambio'!#REF!
Name TC: '[2]Tipos de Cambio'!#REF!
Name TC: '[1]Tipos de Cambio'!#REF!
Name TC: '[2]Tipos de Cambio'!#REF!

Sheet Forecast Drivers
A1: Forecast Drivers
A6: Income statement items | C6: Computation strategy | E6: 2019 | F6: 2020 | G6: 2021 | H6: 2022E | I6: 2023F | J6: 2024F | K6: 2025F | L6: 2026F | M6: 2027F
A7: Brazilian (TAM) Revenues | B7: Domestic Brazilian RPks | C7: Regressed quarterly ln(RPKs) over quarterly ln(real GDP_(t-1)) and ln(Jet fuel price_(t-1) To find elasticities: \epsilon_1=3.62, \epsilon_2=-0.19 | E7: {=TRANSPOSE('Domestic, Brazil estimate'!$B$53:$B$61)} -> 96449372986 | F7: 48695532564 | G7: 66373162099 | H7: 9.6237179e+10 | I7: 9.9065545e+10 | J7: 1.0728522e+11 | K7: 1.1262227e+11 | L7: 1.1677253e+11 | M7: 1.2107574e+11
C8: Growth Rates | E8: - | F8: =F7/E7-1 -> -0.4951182 | G8: =G7/F7-1 -> 0.36302364 | H8: =H7/G7-1 -> 0.44994115 | I8: =I7/H7-1 -> 0.029389528 | J8: =J7/I7-1 -> 0.0829721 | K8: =K7/J7-1 -> 0.049746371 | L8: =L7/K7-1 -> 0.036851174 | M8: =M7/L7-1 -> 0.036851174
C9: Real Gdp Brazil forecasted for 2022-2027 | E9: - | F9: - | G9: - | H9: 0.01 | I9: 0.01 | J9: 0.01 | K9: 0.01 | L9: 0.01 | M9: 0.01
C10: JET FUEL US$ per gallon | E10: 1.86 | F10: 1.1 | G10: 1.69 | H10: 3.43 | I10: 3.1 | J10: 2.38 | K10: 2.38 | L10: 2.38 | M10: =L10 -> 2.38
C11: CAGR 2022-2027, 5 years | D11: ='Domestic, Brazil estimate'!B22 -> 0.04699076
C12: CAGR 8 years 2019-2028, Latam Estimate | D12: =4.1% -> 0.041
C13: CAGR 8 Years 2019-2028 our estimate | D13: ='Domestic, Brazil estimate'!B23 -> 0.033497113
C14: R^2 regression | D14: ='Regression_Brazil '!B90 -> 0.96339276
C15: Recovery Rate market to pre pandemic Levels (2019) vs 2022 | D15: ='Domestic, Brazil estimate'!C13/'Domestic, Brazil estimate'!C10 -> 0.99779995
B17: Market share computation | C17: Assuming Latam and its LCC competitors will keep their actual RPKs as of 2021, their future market share will be driven by their contribution to the market growth. This contribution is estimated by a backward looking smoothed average, reduced by a future competition factor.
C18: (q1+q2+q3)2022/(q1+q2+q3)2019 | D18: =SUM(SS!BM79:BO79)/SUM(SS!AX79:AZ79) -> 0.99955011
C20: Market Share
C21: GOL+AZUL | E21: =Bra_Mkt_Sh!J59 -> 0.61190547 | F21: =Bra_Mkt_Sh!K59 -> 0.67056147 | G21: =Bra_Mkt_Sh!L59 -> 0.68429229 | H21: =Bra_Mkt_Sh!M59 -> 0.65547068 | I21: =Bra_Mkt_Sh!N59 -> 0.65750203 | J21: =Bra_Mkt_Sh!O59 -> 0.66167288 | K21: =Bra_Mkt_Sh!P59 -> 0.6633594 | L21: =Bra_Mkt_Sh!Q59 -> 0.66456434 | M21: =Bra_Mkt_Sh!R59 -> 0.66572645
C22: LATAM | E22: =Bra_Mkt_Sh!J60 -> 0.34715698 | F22: =Bra_Mkt_Sh!K60 -> 0.32492315 | G22: =Bra_Mkt_Sh!L60 -> 0.30506082 | H22: =Bra_Mkt_Sh!M60 -> 0.34050995 | I22: =Bra_Mkt_Sh!N60 -> 0.33830785 | J22: =Bra_Mkt_Sh!O60 -> 0.33215957 | K22: =Bra_Mkt_Sh!P60 -> 0.32839588 | L22: =Bra_Mkt_Sh!Q60 -> 0.32570689 | M22: =Bra_Mkt_Sh!R60 -> 0.32311348
C23: OTHERS | E23: =Bra_Mkt_Sh!J61 -> 0.04093755 | F23: =Bra_Mkt_Sh!K61 -> 0.0045153745 | G23: =Bra_Mkt_Sh!L61 -> 0.010646895 | H23: =Bra_Mkt_Sh!M61 -> 0.0040193713 | I23: =Bra_Mkt_Sh!N61 -> 0.0041901209 | J23: =Bra_Mkt_Sh!O61 -> 0.0061675494 | K23: =Bra_Mkt_Sh!P61 -> 0.0082447229 | L23: =Bra_Mkt_Sh!Q61 -> 0.0097287652 | M23: =Bra_Mkt_Sh!R61 -> 0.011160062
C25: Latam RPKs (mil) | E25: =Bra_Mkt_Sh!J65 -> 33483073 | F25: =Bra_Mkt_Sh!K65 -> 15822306 | G25: =Bra_Mkt_Sh!L65 -> 20247851 | H25: =Bra_Mkt_Sh!M65 -> 32769717 | I25: =Bra_Mkt_Sh!N65 -> 33514652 | J25: =Bra_Mkt_Sh!O65 -> 35635813 | K25: =Bra_Mkt_Sh!P65 -> 36984690 | L25: =Bra_Mkt_Sh!Q65 -> 38033619 | M25: =Bra_Mkt_Sh!R65 -> 39121204
C26: With our estimates Latam recovers in 2022 vs 2019 | D26: =H25/E25 -> 0.97869504
B29: Real Yield per RPk and Revenues in BRL | C29: We considered real yield per RPK constant to the mean level from 2019-2021
C30: Revenues Brazil USDm | E30: 3949.8 | F30: 1304 | G30: 1664.5
C31: Yield Per RPK USD | E31: =E30/(E25/1000) -> 0.11796408 | F31: =F30/(F25/1000) -> 0.082415294 | G31: =G30/(G25/1000) -> 0.082206255
C32: USDBRL | E32: 3.9776027 | F32: 5.3540347 | G32: 5.4278
C33: Nominal Yield per RPK RBL | E33: =E30*E32/(E25/1000) -> 0.46921426 | F33: =F30*F32/(F25/1000) -> 0.44125435 | G33: =G30*G32/(G25/1000) -> 0.44619911 | H33: =H37*(1+H36) -> 0.44351344 | I33: =I37*(1+I36) -> 0.4652456 | J33: =J37*(1+J36) -> 0.4815292 | K33: =K37*(1+K36) -> 0.4971789 | L33: =L37*(1+L36) -> 0.51333721 | M33: =M37*(1+M36) -> 0.53002067
C34: Inflation | E34: 0.0373 | F34: 0.0321 | G34: 0.083 | H34: 0.065 | I34: 0.049 | J34: 0.035 | K34: 0.0325 | L34: 0.0325 | M34: 0.0325
C35: Cumulated inflation (constant 2018) | E35: 0.0373 | F35: 0.07059733 | G35: 0.15945691 | H35: 0.23482161 | I35: 0.29532787 | J35: 0.34066434 | K35: 0.38423593 | L35: 0.4292236 | M35: 0.47567337
C36: Cumulated inflation (constant 2021) | E36: - | F36: - | G36: - | H36: =H34 -> 0.065 | I36: =(1+H36)*(1+I34)-1 -> 0.117185 | J36: =(1+I36)*(1+J34)-1 -> 0.15628647 | K36: =(1+J36)*(1+K34)-1 -> 0.19386579 | L36: =(1+K36)*(1+L34)-1 -> 0.23266642 | M36: =(1+L36)*(1+M34)-1 -> 0.27272808
C37: Real Yield per RPK BRL (constant 2018) | E37: =E33/(1+E35) -> 0.45234191 | F37: =F33/(1+F35) -> 0.41215715 | G37: =G33/(1+G35) -> 0.38483458 | H37: =AVERAGE($E$37:$G$37) -> 0.41644455 | I37: =AVERAGE($E$37:$G$37) -> 0.41644455 | J37: =AVERAGE($E$37:$G$37) -> 0.41644455 | K37: =AVERAGE($E$37:$G$37) -> 0.41644455 | L37: =AVERAGE($E$37:$G$37) -> 0.41644455 | M37: =AVERAGE($E$37:$G$37) -> 0.41644455
C38: Revenues mln BRL | E38: =E30*E32 -> 15710.735 | F38: =F30*F32 -> 6981.6613 | G38: =G30*G32 -> 9034.5731 | H38: =H33*H25/1000 -> 14533.81 | I38: =I33*I25/1000 -> 15592.544 | J38: =J33*J25/1000 -> 17159.684 | K38: =K33*K25/1000 -> 18388.007 | L38: =L33*L25/1000 -> 19524.072 | M38: =M33*M25/1000 -> 20735.047
C39: growth rate % | F39: =F38/E38-1 -> -0.55561206 | G39: =G38/F38-1 -> 0.29404345 | H39: =H38/G38-1 -> 0.60868809 | I39: =I38/H38-1 -> 0.072846286 | J39: =J38/I38-1 -> 0.10050574 | K39: =K38/J38-1 -> 0.071581891 | L39: =L38/K38-1 -> 0.061782932 | M39: =M38/L38-1 -> 0.062024687
C40: CAGR 2020-2027 | D40: =(M38/E38)^(1/8)-1 -> 0.03529368
C41: CAGR 2022-2027, 5 years | D41: =(M38/I38)^(1/5)-1 -> 0.058662686
B43: Futures | C43: We convert Brazilian Revenues in $ by using futures on the exchange rate
C44: Futures BRL/USD | H44: =1/Futures_provvisorio!B3 -> 5.3561864 | I44: =1/AVERAGE(Futures_provvisorio!B4:B15) -> 5.5437494 | J44: =1/AVERAGE(Futures_provvisorio!B16:B27) -> 5.9161387 | K44: =1/AVERAGE(Futures_provvisorio!B28:B39) -> 6.2904621 | L44: =1/AVERAGE(Futures_provvisorio!B40:B51) -> 6.6644452 | M44: =1/AVERAGE(Futures_provvisorio!B52:B62) -> 7.0226961
B46: Brazilian Rev $mil | C46: Brazilian Rev in $mln | H46: =H38/H44 -> 2713.4623 | I46: =I38/I44 -> 2812.6351 | J46: =J38/J44 -> 2900.4872 | K46: =K38/K44 -> 2923.1568 | L46: =L38/L44 -> 2929.587 | M46: =M38/M44 -> 2952.5764
A50: SSC Revenues (USD) | B50: SSC number of passengers | C50: Regressed yearly ln(Number of Passengers) over yearly ln(real GDP_t) and ln(Jet fuel price_t) To find elasticities: \epsilon_1=2.44, \epsilon_2=-0.35 | E50: =SSC_Mkt_Sh!K25 -> 58822802 | F50: =SSC_Mkt_Sh!L25 -> 21481765 | G50: =SSC_Mkt_Sh!M25 -> 41531109 | H50: =SSC_Mkt_Sh!N25 -> 61695850 | I50: =SSC_Mkt_Sh!O25 -> 65504040 | J50: =SSC_Mkt_Sh!P25 -> 73662984 | K50: =SSC_Mkt_Sh!Q25 -> 75470842 | L50: =SSC_Mkt_Sh!R25 -> 77323069 | M50: =SSC_Mkt_Sh!S25 -> 79220753
C51: Growth Rates | F51: =F50/E50-1 -> -0.63480548 | G51: =G50/F50-1 -> 0.93331921 | H51: =H50/G50-1 -> 0.48553341 | I51: =I50/H50-1 -> 0.061725216 | J51: =J50/I50-1 -> 0.12455636 | K51: =K50/J50-1 -> 0.024542282 | L51: =L50/K50-1 -> 0.024542282 | M51: =M50/L50-1 -> 0.024542282
C52: Real SSC GDP forecasted for 2022-2027 | H52: 0.01 | I52: 0.01 | J52: 0.01 | K52: 0.01 | L52: 0.01 | M52: 0.01
C53: JET FUEL US$ per gallon | H53: 3.43 | I53: 3.1 | J53: 2.38 | K53: 2.38 | L53: 2.38 | M53: =L53 -> 2.38
C54: CAGR 2022-2027, 5 years | D54: =(M50/H50)^(1/5)-1 -> 0.051275645
...

Sheet Pro_Forma IS
A1: Item | C1: 2017 | D1: 2018 | E1: 2019 | F1: 2020 | G1: 2021 | H1: 2022E | I1: 2023F | J1: 2024F | K1: 2025F | L1: 2026F | M1: 2027F
C2: 2017 | D2: 2018 | E2: 2019 | F2: 2020 | G2: 2021 | H2: 2022 | I2: 2023 | J2: 2024 | K2: 2025 | L2: 2026 | M2: 2027
B3: REVENUES 000$
B4: Net Passenger Revenue | C4: =SS!AL9 -> 8494477 | D4: =SS!AW9 -> 8708988 | E4: =SS!BB9 -> 9005629 | F4: =SS!BG9 -> 2713774 | G4: =SS!BL9 -> 3342380.6 | H4: ='Forecast Drivers'!H126*10^3 -> 7759817.2 | I4: ='Forecast Drivers'!I126*10^3 -> 9246279.9 | J4: ='Forecast Drivers'!J126*10^3 -> 10229781 | K4: ='Forecast Drivers'!K126*10^3 -> 10580000 | L4: ='Forecast Drivers'!L126*10^3 -> 11112006 | M4: ='Forecast Drivers'!M126*10^3 -> 11704024
B5: Net Cargo Revenue | C5: =Margin!I4 -> 1119430 | D5: =Margin!J4 -> 1186468 | E5: =Margin!K4 -> 1064434 | F5: =Margin!L4 -> 1209893 | G5: =Margin!M4 -> 1541634.6 | H5: ='Drivers Cargo'!H24*10^3 -> 1852457.2 | I5: ='Drivers Cargo'!I24*10^3 -> 2057815.6 | J5: ='Drivers Cargo'!J24*10^3 -> 1793929.6 | K5: ='Drivers Cargo'!K24*10^3 -> 1854026.3 | L5: ='Drivers Cargo'!L24*10^3 -> 1714244.3 | M5: ='Drivers Cargo'!M24*10^3 -> 1771671.4
B6: Other | C6: =Margin!I5 -> 549889 | D6: =Margin!J5 -> 472758 | E6: =Margin!K5 -> 360864 | F6: =Margin!L5 -> 411002 | G6: =Margin!M5 -> 227331.16 | H6: - | I6: - | J6: - | K6: - | L6: - | M6: -
B7: TOTAL OPERATING REVENUES | C7: =SUM(C4:C6) -> 10163796 | D7: =SUM(D4:D6) -> 10368214 | E7: =SUM(E4:E6) -> 10430927 | F7: =SUM(F4:F6) -> 4334669 | G7: =SUM(G4:G6) -> 5111346.3 | H7: =SUM(H4:H6) -> 9612274.4 | I7: =SUM(I4:I6) -> 11304095 | J7: =SUM(J4:J6) -> 12023711 | ... M7: =SUM(M4:M6) -> 13475695
B9: EXPENSES
B10: Wages and Benefits | C10: =Margin!I9 -> -2023634 | D10: =Margin!J9 -> -1819969 | E10: =Margin!K9 -> -1794762 | F10: =Margin!L9+150000 -> -812060 | G10: =Margin!M9 -> -1041899.8 | H10: =E10*(1-27%) -> -1310176.3 | I10: =$H$10/$H$7*I7*(1.02) -> -1571591.1 | J10: =$H$10/$H$7*J7*(1.02) -> -1671638.1 | K10: =$H$10/$H$7*K7*(1.02) -> -1728683.7 | L10: =$H$10/$H$7*L7*(1.02) -> -1783214 | M10: =$H$10/$H$7*M7*(1.02) -> -1873505.2
B11: Aircraft fuel | C11: =Margin!I10 -> -2318815 | D11: =Margin!J10 -> -2983028 | E11: =Margin!K10 -> -2929008 | F11: =Margin!L10 -> -1045343 | G11: =Margin!M10 -> -1487776.5 | H11: =-(SUM('Forecast Drivers'!H25,'Forecast Drivers'!H68,'Forecast Drivers'!H113)/SUM('Forecast Drivers'!$E$25,'Forecast Drivers'!$E$68,'Forecast Drivers'!$E$113))*ABS($E$11)*'Forecast Drivers'!H10/'Forecast Drivers'!$E$10*((1-5.3%)^(1/9))^(H2-$G$2) -> -4367234.7 | I11: =-(SUM('Forecast Drivers'!I25,'Forecast Drivers'!I68,'Forecast Drivers'!I113)/SUM('Forecast Drivers'!$E$25,'Forecast Drivers'!$E$68,'Forecast Drivers'!$E$113))*ABS($E$11)*'Forecast Drivers'!I10/'Forecast Drivers'!$E$10*((1-5.3%)^(1/9))^(I2-$G$2) -> -4523759.4 | J11: =-(SUM('Forecast Drivers'!J25,'Forecast Drivers'!J68,'Forecast Drivers'!J113)/SUM('Forecast Drivers'!$E$25,'Forecast Drivers'!$E$68,'Forecast Drivers'!$E$113))*ABS($E$11)*'Forecast Drivers'!J10/'Forecast Drivers'!$E$10*((1-5.3%)^(1/9))^(J2-$G$2) -> -3974406.7 | K11: =-(SUM('Forecast Drivers'!K25,'Forecast Drivers'!K68,'Forecast Drivers'!K113)/SUM('Forecast Drivers'!$E$25,'Forecast Drivers'!$E$68,'Forecast Drivers'!$E$113))*ABS($E$11)*'Forecast Drivers'!K10/'Forecast Drivers'!$E$10*((1-5.3%)^(1/9))^(K2-$G$2) -> -4109796.3 | L11: =-(SUM('Forecast Drivers'!L25,'Forecast Drivers'!L68,'Forecast Drivers'!L113)/SUM('Forecast Drivers'!$E$25,'Forecast Drivers'!$E$68,'Forecast Drivers'!$E$113))*ABS($E$11)*'Forecast Drivers'!L10/'Forecast Drivers'!$E$10*((1-5.3%)^(1/9))^(L2-$G$2) -> -4234285.2 | M11: =-(SUM('Forecast Drivers'!M25,'Forecast Drivers'!M68,'Forecast Drivers'!M113)/SUM('Forecast Drivers'!$E$25,'Forecast Drivers'!$E$68,'Forecast Drivers'!$E$113))*ABS($E$11)*'Forecast Drivers'!M10/'Forecast Drivers'!$E$10*((1-5.3%)^(1/9))^(M2-$G$2) -> -4364667.2
B12: Selling expenses | C12: =Margin!I11+(Margin!I17-SUM(C18:C19)) -> -395521 | D12: =Margin!J11+(Margin!J17-SUM(D18:D19)) -> -142719 | E12: =Margin!K11+(Margin!K17-SUM(E18:E19)) -> -354679 | F12: =Margin!L11+(Margin!L17-SUM(F18:F19)-150000) -> -34992 | G12: =Margin!M11+(Margin!M17-SUM(G18:G19)) -> -73315.183 | H12: =-SUM('Forecast Drivers'!H25,'Forecast Drivers'!H68,'Forecast Drivers'!H113)/SUM('Forecast Drivers'!$E$25,'Forecast Drivers'!$E$68,'Forecast Drivers'!$E$113)*ABS($E$12) -> -288514.77 | I12: =-SUM('Forecast Drivers'!I25,'Forecast Drivers'!I68,'Forecast Drivers'!I113)/SUM('Forecast Drivers'!$E$25,'Forecast Drivers'!$E$68,'Forecast Drivers'!$E$113)*ABS($E$12) -> -332675.81 | J12: =-SUM('Forecast Drivers'!J25,'Forecast Drivers'!J68,'Forecast Drivers'!J113)/SUM('Forecast Drivers'!$E$25,'Forecast Drivers'!$E$68,'Forecast Drivers'!$E$113)*ABS($E$12) -> -383006.86 | K12: =-SUM('Forecast Drivers'!K25,'Forecast Drivers'!K68,'Forecast Drivers'!K113)/SUM('Forecast Drivers'!$E$25,'Forecast Drivers'!$E$68,'Forecast Drivers'!$E$113)*ABS($E$12) -> -398457.79 | L12: =-SUM('Forecast Drivers'!L25,'Forecast Drivers'!L68,'Forecast Drivers'!L113)/SUM('Forecast Drivers'!$E$25,'Forecast Drivers'!$E$68,'Forecast Drivers'!$E$113)*ABS($E$12) -> -413018.89 | M12: =-SUM('Forecast Drivers'!M25,'Forecast Drivers'!M68,'Forecast Drivers'!M113)/SUM('Forecast Drivers'!$E$25,'Forecast Drivers'!$E$68,'Forecast Drivers'!$E$113)*ABS($E$12) -> -428320.37
B13: Depreciation and Amortization | C13: =Margin!I12 -> -1001625 | D13: =Margin!J12 -> -1372628 | E13: =Margin!K12 -> -1469976 | F13: =Margin!L12 -> -1389387 | G13: =Margin!M12 -> -1165394.2 | H13: =-'Capex.'!AV94 -> -1183741.6 | I13: =-'Capex.'!AW94 -> -1248559.3 | J13: =-'Capex.'!AX94 -> -1275538.5 | K13: =-'Capex.'!AY94 -> -1319446.7 | L13: =-'Capex.'!AZ94 -> -1363935.4 | M13: =-'Capex.'!BA94 -> -1424148.7
B14: Other Rental and Landing Fees | C14: =Margin!I13 -> -1172129 | D14: =Margin!J13 -> -1206881 | E14: =Margin!K13 -> -1275859 | F14: =Margin!L13 -> -720004 | G14: =Margin!M13 -> -755187.96 | H14: =-(SUM('Forecast Drivers'!H25,'Forecast Drivers'!H68,'Forecast Drivers'!H113)/SUM('Forecast Drivers'!$E$25,'Forecast Drivers'!$E$68,'Forecast Drivers'!$E$113))*ABS($E$14) -> -1037851.6 | I14: =-(SUM('Forecast Drivers'!I25,'Forecast Drivers'!I68,'Forecast Drivers'!I113)/SUM('Forecast Drivers'!$E$25,'Forecast Drivers'!$E$68,'Forecast Drivers'!$E$113))*ABS($E$14) -> -1196708.6 | J14: =-(SUM('Forecast Drivers'!J25,'Forecast Drivers'!J68,'Forecast Drivers'!J113)/SUM('Forecast Drivers'!$E$25,'Forecast Drivers'!$E$68,'Forecast Drivers'!$E$113))*ABS($E$14) -> -1377760.6 | K14: =-(SUM('Forecast Drivers'!K25,'Forecast Drivers'!K68,'Forecast Drivers'!K113)/SUM('Forecast Drivers'!$E$25,'Forecast Drivers'!$E$68,'Forecast Drivers'!$E$113))*ABS($E$14) -> -1433341 | L14: =-(SUM('Forecast Drivers'!L25,'Forecast Drivers'!L68,'Forecast Drivers'!L113)/SUM('Forecast Drivers'!$E$25,'Forecast Drivers'!$E$68,'Forecast Drivers'!$E$113))*ABS($E$14) -> -1485720.5 | M14: =-(SUM('Forecast Drivers'!M25,'Forecast Drivers'!M68,'Forecast Drivers'!M113)/SUM('Forecast Drivers'!$E$25,'Forecast Drivers'!$E$68,'Forecast Drivers'!$E$113))*ABS($E$14) -> -1540763.3
B15: Passenger Services | C15: =Margin!I14 -> -288662 | D15: =Margin!J14 -> -280279 | E15: =Margin!K14 -> -261330 | F15: =Margin!L14 -> -97689 | G15: =Margin!M14 -> -77362.938 | H15: =-SUM('Forecast Drivers'!H25,'Forecast Drivers'!H68,'Forecast Drivers'!H113)/SUM('Forecast Drivers'!$E$25,'Forecast Drivers'!$E$68,'Forecast Drivers'!$E$113)*ABS($E$15) -> -212579.73 | I15: =-SUM('Forecast Drivers'!I25,'Forecast Drivers'!I68,'Forecast Drivers'!I113)/SUM('Forecast Drivers'!$E$25,'Forecast Drivers'!$E$68,'Forecast Drivers'!$E$113)*ABS($E$15)*1.05 -> -257373.79 | J15: =-SUM('Forecast Drivers'!J25,'Forecast Drivers'!J68,'Forecast Drivers'!J113)/SUM('Forecast Drivers'!$E$25,'Forecast Drivers'!$E$68,'Forecast Drivers'!$E$113)*ABS($E$15)*1.05 -> -296312.27 | K15: =-SUM('Forecast Drivers'!K25,'Forecast Drivers'!K68,'Forecast Drivers'!K113)/SUM('Forecast Drivers'!$E$25,'Forecast Drivers'!$E$68,'Forecast Drivers'!$E$113)*ABS($E$15)*1.05 -> -308265.85 | L15: =-SUM('Forecast Drivers'!L25,'Forecast Drivers'!L68,'Forecast Drivers'!L113)/SUM('Forecast Drivers'!$E$25,'Forecast Drivers'!$E$68,'Forecast Drivers'!$E$113)*ABS($E$15)*1.05 -> -319531.01 | M15: =-SUM('Forecast Drivers'!M25,'Forecast Drivers'!M68,'Forecast Drivers'!M113)/SUM('Forecast Drivers'!$E$25,'Forecast Drivers'!$E$68,'Forecast Drivers'!$E$113)*ABS($E$15)*1.05 -> -331368.95
B16: Aircraft Rentals | C16: =Margin!I15 -> -579552 | D16: =Margin!J15 -> 0 | E16: =Margin!K15 -> 0 | F16: =Margin!L15 -> 0 | G16: =Margin!M15 -> -120629 | H16: -197000 | I16: -109000 | J16: -15000
B17: Aircraft maintenance | C17: =Margin!I16 -> -430824 | D17: =Margin!J16 -> -366627 | E17: =Margin!K16 -> -444612 | F17: =Margin!L16 -> -472382 | G17: =Margin!M16 -> -533738.55 | H17: =-SUM('Forecast Drivers'!H25,'Forecast Drivers'!H68,'Forecast Drivers'!H113)/SUM('Forecast Drivers'!$E$25,'Forecast Drivers'!$E$68,'Forecast Drivers'!$E$113)*ABS(E17) -> -361671.06 | I17: =-SUM('Forecast Drivers'!I25,'Forecast Drivers'!I68,'Forecast Drivers'!I113)/SUM('Forecast Drivers'!$E$25,'Forecast Drivers'!$E$68,'Forecast Drivers'!$E$113)*ABS(F17) -> -443076.88 | J17: =-SUM('Forecast Drivers'!J25,'Forecast Drivers'!J68,'Forecast Drivers'!J113)/SUM('Forecast Drivers'!$E$25,'Forecast Drivers'!$E$68,'Forecast Drivers'!$E$113)*ABS(G17) -> -576367.71 | K17: =-SUM('Forecast Drivers'!K25,'Forecast Drivers'!K68,'Forecast Drivers'!K113)/SUM('Forecast Drivers'!$E$25,'Forecast Drivers'!$E$68,'Forecast Drivers'!$E$113)*ABS(H17) -> -406312.89 | L17: =-SUM('Forecast Drivers'!L25,'Forecast Drivers'!L68,'Forecast Drivers'!L113)/SUM('Forecast Drivers'!$E$25,'Forecast Drivers'!$E$68,'Forecast Drivers'!$E$113)*ABS(I17) -> -515957.02 | M17: =-SUM('Forecast Drivers'!M25,'Forecast Drivers'!M68,'Forecast Drivers'!M113)/SUM('Forecast Drivers'!$E$25,'Forecast Drivers'!$E$68,'Forecast Drivers'!$E$113)*ABS(J17) -> -696037.91
B18: Administrative expenses | C18: -873000 | D18: -952800 | E18: -736300 | F18: -735200 | G18: -439494 | H18: =-SUM('Forecast Drivers'!H25,'Forecast Drivers'!H68,'Forecast Drivers'!H113)/SUM('Forecast Drivers'!$E$25,'Forecast Drivers'!$E$68,'Forecast Drivers'!$E$113)*ABS(E18) -> -598945.6 | I18: =-SUM('Forecast Drivers'!I25,'Forecast Drivers'!I68,'Forecast Drivers'!I113)/SUM('Forecast Drivers'!$E$25,'Forecast Drivers'!$E$68,'Forecast Drivers'!$E$113)*ABS(F18) -> -689590.46 | J18: =-SUM('Forecast Drivers'!J25,'Forecast Drivers'!J68,'Forecast Drivers'!J113)/SUM('Forecast Drivers'!$E$25,'Forecast Drivers'!$E$68,'Forecast Drivers'!$E$113)*ABS(G18) -> -474595.94 | K18: =-SUM('Forecast Drivers'!K25,'Forecast Drivers'!K68,'Forecast Drivers'!K113)/SUM('Forecast Drivers'!$E$25,'Forecast Drivers'!$E$68,'Forecast Drivers'!$E$113)*ABS(H18) -> -672874.73 | L18: =-SUM('Forecast Drivers'!L25,'Forecast Drivers'!L68,'Forecast Drivers'!L113)/SUM('Forecast Drivers'!$E$25,'Forecast Drivers'!$E$68,'Forecast Drivers'!$E$113)*ABS(I18) -> -803018.75 | M18: =-SUM('Forecast Drivers'!M25,'Forecast Drivers'!M68,'Forecast Drivers'!M113)/SUM('Forecast Drivers'!$E$25,'Forecast Drivers'!$E$68,'Forecast Drivers'!$E$113)*ABS(J18) -> -573135.45
B19: General expenses | C19: -365500 | D19: -356300 | E19: -422800 | F19: -692900 | G19: -535824 | H19: =AVERAGE($E$19:$G$19) -> -550508 | I19: =H19*1.02 -> -561518.16 | J19: =I19*1.02 -> -572748.52 | K19: =J19*1.02 -> -584203.49 | L19: =K19*1.02 -> -595887.56 | M19: =L19*1.02 -> -607805.31
B20: TOTAL OPERATING EXPENSES | C20: =SUM(C10:C19) -> -9449262 | D20: =SUM(D10:D19) -> -9481231 | E20: =SUM(E10:E19) -> -9689326 | F20: =SUM(F10:F19) -> -5999957 | G20: =SUM(G10:G19) -> -6230622.2 | H20: =SUM(H10:H19) -> -10108223 | I20: =SUM(I10:I19) -> -10933854 | J20: =SUM(J10:J19) -> -10617375 | ... M20: =SUM(M10:M19) -> -11839752
B22: OPERATING INCOME (LOSS) | C22: =C7+C20 -> 714534 | D22: =D7+D20 -> 886983 | E22: =E7+E20 -> 741601 | F22: =F7+F20 -> -1665288 | G22: =G7+G20 -> -1119275.8 | H22: =H7+H20 -> -495948.82 | I22: =I7+I20 -> 370241.95 | J22: =J7+J20 -> 1406335.7 | ... M22: =M7+M20 -> 1635942.6
B23: Operating Margin | C23: =C22/C7 -> 0.070301883 | D23: =D22/D7 -> 0.085548292 | E23: =E22/E7 -> 0.071096366 | F23: =F22/F7 -> -0.38417882 | G23: =G22/G7 -> -0.21897867 | H23: =H22/H7 -> -0.051595366 | I23: =I22/I7 -> 0.032752904 | J23: =J22/J7 -> 0.11696354 | ... M23: =M22/M7 -> 0.1213995
H24: 1158 | I24: 2003 | J24: 2429 | K24: 2773 | L24: 3087 | M24: 3310
B25: EBITDAR | C25: =C22-C16-C13 -> 2295711 | D25: =D22-D16-D13 -> 2259611 | E25: =E22-E16-E13 -> 2211577 | F25: =F22-F16-F13 -> -275901 | G25: =G22-G16-G13 -> 166747.32 | H25: =H7+SUM(H10:H12,H14:H15,H17:H19) -> 884792.78 | I25: =I7+SUM(I10:I12,I14:I15,I17:I19) -> 1727801.3 | J25: =J7+SUM(J10:J12,J14:J15,J17:J19) -> 2696874.3 | K25: =K7+SUM(K10:K12,K14:K15,K17:K19) -> 2792090.8 | L25: =L7+SUM(L10:L12,L14:L15,L17:L19) -> 2675617.7 | M25: =M7+SUM(M10:M12,M14:M15,M17:M19) -> 3060091.2
B26: EBITDAR margin | C26: =C25/C7 -> 0.22587142 | D26: =D25/D7 -> 0.21793638 | E26: =E25/E7 -> 0.21202114 | F26: =F25/F7 -> -0.063649843 | G26: =G25/G7 -> 0.032622974 | H26: =H25/H7 -> 0.092048222 | I26: =I25/I7 -> 0.15284737 | J26: =J25/J7 -> 0.22429633 | ... M26: =M25/M7 -> 0.22708226
B28: EBITDA | C28: =C25+C16 -> 1716159 | D28: =D25+D16 -> 2259611 | E28: =E25+E16 -> 2211577 | F28: =F25+F16 -> -275901 | G28: =G25+G16 -> 46118.32 | H28: =H25+H16 -> 687792.78 | I28: =I25+I16 -> 1618801.3 | J28: =J25+J16 -> 2681874.3 | ... M28: =M25+M16 -> 3060091.2
B29: EBITDA Margin | C29: =C28/C7 -> 0.1688502 | D29: =D28/D7 -> 0.21793638 | E29: =E28/E7 -> 0.21202114 | F29: =F28/F7 -> -0.063649843 | G29: =G28/G7 -> 0.0090227344 | H29: =H28/H7 -> 0.071553593 | I29: =I28/I7 -> 0.14320485 | J29: =J28/J7 -> 0.2230488 | ... M29: =M28/M7 -> 0.22708226
B31: EBIT | C31: =C7+C20 -> 714534 | D31: =D7+D20 -> 886983 | E31: =E7+E20 -> 741601 | F31: =F7+F20 -> -1665288 | G31: =G7+G20 -> -1119275.8 | H31: =H7+H20 -> -495948.82 | I31: =I7+I20 -> 370241.95 | J31: =J7+J20 -> 1406335.7 | ... M31: =M7+M20 -> 1635942.6
B32: EBIT Margin | C32: =C31/C7 -> 0.070301883 | D32: =D31/D7 -> 0.085548292 | E32: =E31/E7 -> 0.071096366 | F32: =F31/F7 -> -0.38417882 | G32: =G31/G7 -> -0.21897867 | H32: =H31/H7 -> -0.051595366 | I32: =I31/I7 -> 0.032752904 | J32: =J31/J7 -> 0.11696354 | ... M32: =M31/M7 -> 0.1213995
B34: OTHER INCOME ( EXPENSE )
B35: Interest Expense Gross | H35: =-Sch_Deb!P43 -> -769659.25 | I35: =-Sch_Deb!Q43 -> #REF! | J35: =-Sch_Deb!R43 -> #REF! | K35: =-Sch_Deb!S43 -> #REF! | L35: =-Sch_Deb!T43 -> #REF! | M35: =-Sch_Deb!U43 -> #REF!
B36: Tax shield
B37: Interest expense net
B39: PROFIT BEFORE TAX AND MINORITY INTEREST | H39: =H31+H35 -> -1265608.1 | I39: =I31+I35 -> #REF! | J39: =J31+J35 -> #REF! | K39: =K31+K35 -> #REF! | L39: =L31+L35 -> #REF! | M39: =M31+M35 -> #REF!
B41: Income Tax Expense | H41: =-26%*H39 -> 329058.1 | I41: =-26%*I39 -> #REF! | J41: =-26%*J39 -> #REF! | K41: =-26%*K39 -> #REF! | L41: =-26%*L39 -> #REF! | M41: =-26%*M39 -> #REF!
B43: PROFIT BEFORE MINORITY INTEREST | H43: =H39+H41 -> -936549.97 | I43: =I39+I41 -> #REF! | J43: =J39+J41 -> #REF! | K43: =K39+K41 -> #REF! | L43: =L39+L41 -> #REF! | M43: =M39+M41 -> #REF!
B44: Attributable to:
B45: Shareholders
B46: Minority Interest
B49: PROFIT FOR THE YEAR
B50: Net Margin

Sheet Pro_Forma BS
A1: (in US$ millions except per share and capital stock data) | C1: 2017 | D1: 2018 | E1: 2019 | F1: 2020 | G1: 2021 | H1: 2022E | I1: 2023F | J1: 2024F | K1: 2025F | L1: 2026F | M1: 2027F
C2: 2017 | D2: 2018 | E2: 2019 | F2: 2020 | G2: 2021 | H2: 2022 | I2: 2023 | J2: 2024 | K2: 2025 | L2: 2026 | M2: 2027
B3: ASSETS | C3: 18797972 | D3: 20078722 | E3: 21087806 | F3: 15650090 | G3: 13312434
B4: Cash, and cash equivalents | C4: 1142004 | D4: 1081642 | E4: 1072579 | F4: 1695841 | G4: 1046835
B5: Other financial assets | C5: 559919 | D5: 383984 | E5: 499504 | F5: 50250 | G5: 101138
B6: Other non-financial assets | C6: 221188 | D6: 290476 | E6: 313449 | F6: 155892 | G6: 108368 | H6: =+'Pro_Forma IS'!H$7*'Working Cap'!$O$49 -> 248522.65 | I6: =+'Pro_Forma IS'!I$7*'Working Cap'!$O$49 -> 292264.2 | J6: =+'Pro_Forma IS'!J$7*'Working Cap'!$O$49 -> 310869.66 | K6: =+'Pro_Forma IS'!K$7*'Working Cap'!$O$49 -> 321478.25 | L6: =+'Pro_Forma IS'!L$7*'Working Cap'!$O$49 -> 331619.1 | M6: =+'Pro_Forma IS'!M$7*'Working Cap'!$O$49 -> 348410.3
B7: Trade and other accounts receivable | C7: 1214050 | D7: 1162582 | E7: 1244348 | F7: 599381 | G7: 902672 | H7: =+'Working Cap'!AI$15 -> 1091172.2 | I7: =+'Working Cap'!AJ$15 -> 1283225.4 | J7: =+'Working Cap'!AK$15 -> 1364915.2 | K7: =+'Working Cap'!AL$15 -> 1411493.7 | L7: =+'Working Cap'!AM$15 -> 1456018.4 | M7: =+'Working Cap'!AN$15 -> 1529742.5
B8: Accounts receivable from related entities | C8: 2582 | D8: 2931 | E8: 19645 | F8: 158 | G8: 724 | H8: 0 | I8: 0 | J8: 0 | K8: 0 | L8: 0 | M8: 0
B9: Inventories | C9: 236666 | D9: 279344 | E9: 354232 | F9: 323574 | G9: 287337 | H9: =-SUM('Pro_Forma IS'!H$11:H$12,'Pro_Forma IS'!H$14:H$19)*('Working Cap'!L$73/360) -> 327838.15 | I9: =-SUM('Pro_Forma IS'!I$11:I$12,'Pro_Forma IS'!I$14:I$19)*('Working Cap'!M$73/360) -> 349339.99 | J9: =-SUM('Pro_Forma IS'!J$11:J$12,'Pro_Forma IS'!J$14:J$19)*('Working Cap'!N$73/360) -> 330244.66 | K9: =-SUM('Pro_Forma IS'!K$11:K$12,'Pro_Forma IS'!K$14:K$19)*('Working Cap'!O$73/360) -> 340709.46 | L9: =-SUM('Pro_Forma IS'!L$11:L$12,'Pro_Forma IS'!L$14:L$19)*('Working Cap'!P$73/360) -> 360263.87 | M9: =-SUM('Pro_Forma IS'!M$11:M$12,'Pro_Forma IS'!M$14:M$19)*('Working Cap'!Q$73/360) -> 367784.8
B10: Tax assets | C10: 77987 | D10: 69134 | E10: 29321 | F10: 42320 | G10: 41264
B11: Non- current assets and disposal groups held for sale | C11: 291103 | D11: 5768 | E11: 485150 | F11: 276122 | G11: 146792 | H11: 0 | I11: 0 | J11: 0 | K11: 0 | L11: 0 | M11: 0
B12: TOTAL CURRENT ASSETS | C12: 3745499 | D12: 3275861 | E12: 4018228 | F12: 3143538 | G12: 2635130 | H12: =+SUM(H4:H11) -> 1667533 | I12: =+SUM(I4:I11) -> 1924829.6 | J12: =+SUM(J4:J11) -> 2006029.5 | K12: =+SUM(K4:K11) -> 2073681.4 | L12: =+SUM(L4:L11) -> 2147901.4 | M12: =+SUM(M4:M11) -> 2245937.6
B13: Property and equipment | C13: 10065335 | D13: 12501809 | E13: 12919618 | F13: 10730269 | G13: 9489867 | H13: =+CAPEX!AV70 -> 9404186.8 | I13: =+CAPEX!AW70 -> 10110376 | J13: =+CAPEX!AX70 -> 10142086 | K13: =+CAPEX!AY70 -> 10413601 | L13: =+CAPEX!AZ70 -> 10651208 | M13: =+CAPEX!BA70 -> 11099610
B14: Goodwill | C14: 2672550 | D14: 2294072 | E14: 2209576 | F14: 0 | G14: 0 | H14: 0 | I14: 0 | J14: 0 | K14: 0 | L14: 0 | M14: 0
B15: Intangible assets other than goodwill | C15: 1617247 | D15: 1441072 | E15: 1448241 | F15: 1046559 | G15: 1018892 | H15: =CAPEX!Z13 -> 1018765 | I15: =CAPEX!AA13 -> 1018765 | J15: =CAPEX!AB13 -> 1018765 | K15: =CAPEX!AC13 -> 1018765 | L15: =CAPEX!AD13 -> 1018765 | M15: =CAPEX!AE13 -> 1018765
B16: Other non- current assets | C16: 697341 | D16: 565908 | E16: 492143 | F16: 729724 | G16: 168545
B17: TOTAL NON-CURRENT ASSETS | C17: 15052473 | D17: 16802861 | E17: 17069578 | F17: 12506552 | G17: 10677304 | H17: =+SUM(H13:H16) -> 10422952 | I17: =+SUM(I13:I16) -> 11129141 | J17: =+SUM(J13:J16) -> 11160851 | K17: =+SUM(K13:K16) -> 11432366 | L17: =+SUM(L13:L16) -> 11669973 | M17: =+SUM(M13:M16) -> 12118375
B19: LIABILITIES AND SHAREHOLDERS' EQUITY | C19: 18797972 | D19: 20078722 | E19: 21087806 | F19: 15650090 | G19: 13312434
B20: Other financial liabilities | C20: 1300949 | D20: 1794286 | E20: 1885660 | F20: 3055730 | G20: 4453451
B21: Trade and other accounts payables | C21: 1695202 | D21: 1674303 | E21: 2222874 | F21: 2322125 | G21: 4860153 | H21: =SUM('Pro_Forma IS'!H$11:H$12,'Pro_Forma IS'!H$14:H$19)*('Working Cap'!$O$68/365) -> -3906955.1 | I21: =SUM('Pro_Forma IS'!I$11:I$12,'Pro_Forma IS'!I$14:I$19)*('Working Cap'!$O$68/365) -> -4163199.7 | J21: =SUM('Pro_Forma IS'!J$11:J$12,'Pro_Forma IS'!J$14:J$19)*('Working Cap'!$O$68/365) -> -3935634.3 | K21: =SUM('Pro_Forma IS'!K$11:K$12,'Pro_Forma IS'!K$14:K$19)*('Working Cap'!$O$68/365) -> -4060346.8 | L21: =SUM('Pro_Forma IS'!L$11:L$12,'Pro_Forma IS'!L$14:L$19)*('Working Cap'!$O$68/365) -> -4293383.2 | M21: =SUM('Pro_Forma IS'!M$11:M$12,'Pro_Forma IS'!M$14:M$19)*('Working Cap'!$O$68/365) -> -4383012.5
B22: Tax liabilities | C22: 3511 | D22: 3738 | E22: 11925 | F22: 656 | G22: 675
B23: Other non-financial liabilities | C23: 2843052 | D23: 2459922 | E23: 2840483 | F23: 2113377 | G23: 3022050 | H23: ='Working Cap'!$D$39*'Pro_Forma IS'!H$4 -> 1301269.8 | I23: ='Working Cap'!$D$39*'Pro_Forma IS'!I$4 -> 1550539.7 | J23: ='Working Cap'!$D$39*'Pro_Forma IS'!J$4 -> 1715466.3 | K23: ='Working Cap'!$D$39*'Pro_Forma IS'!K$4 -> 1774195.7 | L23: ='Working Cap'!$D$39*'Pro_Forma IS'!L$4 -> 1863409.6 | M23: ='Working Cap'!$D$39*'Pro_Forma IS'!M$4 -> 1962686.9
B24: TOTAL CURRENT LIABILITIES | C24: 5842714 | D24: 5932249 | E24: 6960942 | F24: 7491888 | G24: 12336329 | H24: =+SUM(H20:H23) -> -2605685.4 | I24: =+SUM(I20:I23) -> -2612660 | J24: =+SUM(J20:J23) -> -2220168 | K24: =+SUM(K20:K23) -> -2286151.1 | L24: =+SUM(L20:L23) -> -2429973.6 | M24: =+SUM(M20:M23) -> -2420325.6
B25: Other financial liabilities | C25: 6605508 | D25: 8359462 | E25: 8530418 | F25: 7803801 | G25: 5948702
B26: Accounts payable | C26: 498832 | D26: 529277 | E26: 619110 | F26: 651600 | G26: 472426 | H26: 0 | I26: 0 | J26: 0 | K26: 0 | L26: 0 | M26: 0
B27: Other provisions | C27: 374593 | D27: 303495 | E27: 286403 | F27: 396423 | G27: 712581
B28: Deferred tax liabilities | C28: 949697 | D28: 786571 | E28: 616803 | F28: 588359 | G28: 341011
B29: Employee benefits | C29: 101087 | D29: 82365 | E29: 93570 | F29: 384280 | G29: 56233
B30: Other non-financial liabilities | C30: 158305 | D30: 644702 | E30: 851383 | F30: 74116 | G30: 512056 | H30: 0 | I30: 0 | J30: 0 | K30: 0 | L30: 0 | M30: 0
B31: TOTAL NON-CURRENT LIABILITIES | C31: 8688022 | D31: 10705872 | E31: 10997687 | F31: 702008 | G31: 8043009 | H31: =+SUM(H25:H30) -> 0 | I31: =+SUM(I25:I30) -> 0 | J31: =+SUM(J25:J30) -> 0 | K31: =+SUM(K25:K30) -> 0 | L31: =+SUM(L25:L30) -> 0 | M31: =+SUM(M25:M30) -> 0
B33: TOTAL LIABILITIES | C33: 14530736 | D33: 16638121 | E33: 17958629 | F33: 10600587 | G33: 20379338
B35: Share capital | C35: 3146265 | D35: 3146265 | E35: 3146265 | F35: 3146265 | G35: 3146265
B36: Retained earnings | C36: 475118 | D36: 218971 | E36: 352272 | F36: -4193615 | G36: -8841106
B37: Treasury Shares | C37: -178 | D37: -178 | E37: -178 | F37: -178 | G37: -178
B38: Other reserves | C38: 554884 | D38: -4365 | E38: -367577 | F38: -1388185 | G38: -1361529
B39: Equity attributable to the parent company’s equity holders | C39: 4176089 | D39: 3360693 | E39: 3130782 | F39: -2435713 | G39: -7056548
B40: Minority interest | C40: 91147 | D40: 79908 | E40: -1605 | F40: -6673 | G40: -10356
B41: TOTAL NET EQUITY | C41: 4267236 | D41: 3440601 | E41: 3129177 | F41: -2442386 | G41: -7066904 | H41: =+SUM(H35:H40) -> 0 | I41: =+SUM(I35:I40) -> 0 | J41: =+SUM(J35:J40) -> 0 | K41: =+SUM(K35:K40) -> 0 | L41: =+SUM(L35:L40) -> 0 | M41: =+SUM(M35:M40) -> 0
B46: Balance Sheet
B49: (in US$ millions except per share and capital stock data)
...

Sheet Cash Flow
I3: 2022 | J3: 2023 | K3: 2024 | L3: 2025 | M3: 2026 | N3: 2027 | O3: 2028 | P3: 2029 | Q3: 2030 | R3: 2031 | S3: 2032 | T3: 2033 | U3: 2034 | V3: 2035 | W3: 2036 | X3: 2037
E4: 2018 | F4: 2019 | G4: 2020 | H4: 2021 | I4: 2022E | J4: 2023F | K4: 2024F | L4: 2025F | M4: 2026F | N4: 2027F | O4: 2028 FF | P4: 2029 FF | Q4: 2030 FF | R4: 2031 FF | S4: 2032 FF | T4: 2033 FF | U4: 2034 FF | V4: 2035 FF | W4: 2036 FF | X4: 2037 FF
D5: EBITDA | E5: ='Pro_Forma IS'!D28 -> 2259611 | F5: ='Pro_Forma IS'!E28 -> 2211577 | G5: ='Pro_Forma IS'!F28 -> -275901 | H5: ='Pro_Forma IS'!G28 -> 46118.32 | I5: ='Pro_Forma IS'!H28 -> 687792.78 | J5: ='Pro_Forma IS'!I28 -> 1618801.3 | K5: ='Pro_Forma IS'!J28 -> 2681874.3 | L5: ='Pro_Forma IS'!K28 -> 2792090.8 | ... N5: ='Pro_Forma IS'!M28 -> 3060091.2 | O5: =N5 -> 3060091.2 | P5: =O5 -> 3060091.2 | Q5: =P5 -> 3060091.2 | R5: =Q5 -> 3060091.2 | S5: =R5 -> 3060091.2 | T5: =S5 -> 3060091.2 | U5: =T5 -> 3060091.2 | V5: =U5 -> 3060091.2 | ... X5: =W5 -> 3060091.2
D6: -ΔWC | E6: =-('Pro_Forma BS'!D61-'Pro_Forma BS'!C61) -> -74311 | F6: =-('Pro_Forma BS'!E61-'Pro_Forma BS'!D61) -> 963622 | G6: =-('Pro_Forma BS'!F61-'Pro_Forma BS'!E61) -> 278715 | H6: =-('Pro_Forma BS'!G61-'Pro_Forma BS'!F61) -> 2783730 | I6: =-('Pro_Forma BS'!H61-'Pro_Forma BS'!G61) -> -5781158.7 | J6: =-('Pro_Forma BS'!I61-'Pro_Forma BS'!H61) -> 179683.76 | K6: =-('Pro_Forma BS'!J61-'Pro_Forma BS'!I61) -> -43960.305 | L6: =-('Pro_Forma BS'!K61-'Pro_Forma BS'!J61) -> 83446.703 | ... N6: =-('Pro_Forma BS'!M61-'Pro_Forma BS'!L61) -> 65353.6 | O6: =N6-($N$6/5) -> 52282.88 | P6: =O6-($N$6/5) -> 39212.16 | Q6: =P6-($N$6/5) -> 26141.44 | R6: =Q6-($N$6/5) -> 13070.72 | S6: =R6-($N$6/5) -> 0 | T6: =S6-($N$6/5) -> -13070.72 | U6: =T6-($N$6/5) -> -26141.44 | V6: =U6-($N$6/5) -> -39212.16 | ... X6: =W6-($N$6/5) -> -65353.6 | AA6: g | AB6: =2% -> 0.02
D7: -taxes | E7: =IF(26%*'Pro_Forma IS'!D31>0,-26%*'Pro_Forma IS'!D31,0) -> -230615.58 | F7: =IF(26%*'Pro_Forma IS'!E31>0,-26%*'Pro_Forma IS'!E31,0) -> -192816.26 | G7: =IF(26%*'Pro_Forma IS'!F31>0,-26%*'Pro_Forma IS'!F31,0) -> 0 | H7: =IF(26%*'Pro_Forma IS'!G31>0,-26%*'Pro_Forma IS'!G31,0) -> 0 | I7: =-'Pro_Forma IS'!H31*26% -> 128946.69 | J7: =-'Pro_Forma IS'!I31*26% -> -96262.907 | K7: =-'Pro_Forma IS'!J31*26% -> -365647.29 | L7: =-'Pro_Forma IS'!K31*26% -> -382887.47 | M7: =-'Pro_Forma IS'!L31*26% -> -341037.4 | N7: =-'Pro_Forma IS'!M31*26% -> -425345.07 | O7: =N7*(1.02) -> -433851.97 | P7: =O7*(1.02) -> -442529.01 | Q7: =P7*(1.02) -> -451379.59 | R7: =Q7*(1.02) -> -460407.18 | S7: =R7*(1.02) -> -469615.33 | T7: =S7*(1.02) -> -479007.63 | U7: =T7*(1.02) -> -488587.79 | V7: =U7*(1.02) -> -498359.54 | ... X7: =W7*(1.02) -> -518493.27 | AA7: wacc | AB7: =9.57% -> 0.0957
D8: substitution in payment | I8: =Cap_Inc!$M$39 -> 4561861 | J8: =J9/I9-1 -> -5.2285111 | K8: =K9/J9-1 -> 0.33488257 | L8: =L9/K9-1 -> 0.096988356 | M8: =M9/L9-1 -> 0.0095492808 | N8: =N9/M9-1 -> 0.072978384 | O8: =O9/N9-1 -> 0.067680545 | P8: =P9/O9-1 -> 0.062382707 | Q8: =Q9/P9-1 -> 0.057084869 | ... X8: =X9/W9-1 -> 0.02
D9: Cash Flow from operations | E9: =E5+E6+E7 -> 1954684.4 | F9: =F5+F6+F7 -> 2982382.7 | G9: =G5+G6+G7 -> 2814 | H9: =H5+H6+H7 -> 2829848.3 | I9: =I5+I6+I7+I8 -> -402558.28 | J9: =J5+J6+J7 -> 1702222.1 | K9: =K5+K6+K7 -> 2272266.7 | L9: =L5+L6+L7 -> 2492650.1 | M9: =M5+M6+M7 -> 2516453.1 | N9: =N5+N6+N7 -> 2700099.8 | O9: =N9*(1+AJ10) -> 2882844 | P9: =O9*(1+AK10) -> 3062683.6 | Q9: =P9*(1+AL10) -> 3237516.5 | R9: =Q9*(1+AM10) -> 3405177.9 | S9: =R9*(1+AN10) -> 3563481.8 | T9: =S9*(1+AO10) -> 3710266.5 | U9: =T9*(1+AP10) -> 3843441 | V9: =U9*(1+AQ10) -> 3961033.7 | ... X9: =W9*(1+AS10) -> 4142464 | AG9: Target | AH9: 0.02 | AJ9: 1 | AK9: 2 | AL9: 3 | AM9: 4 | AN9: 5 | AO9: 6 | AP9: 7 | AQ9: 8 | AR9: 9 | AS9: 10
D10: -capex | I10: =-CAPEX!AV114 -> -1231085.2 | J10: =-CAPEX!AW114 -> -1954840.7 | K10: =-CAPEX!AX114 -> -1307354.3 | L10: =-CAPEX!AY114 -> -1590993.9 | M10: =-CAPEX!AZ114 -> -1601573.2 | N10: =-CAPEX!BA114 -> -1872582.9 | O10: =(N10-(($N$10-$X$10)/10)) -> #REF! | P10: =(O10-(($N$10-$X$10)/10)) -> #REF! | Q10: =(P10-(($N$10-$X$10)/10)) -> #REF! | R10: =(Q10-(($N$10-$X$10)/10)) -> #REF! | S10: =(R10-(($N$10-$X$10)/10)) -> #REF! | T10: =(S10-(($N$10-$X$10)/10)) -> #REF! | U10: =(T10-(($N$10-$X$10)/10)) -> #REF! | V10: =(U10-(($N$10-$X$10)/10)) -> #REF! | W10: =(V10-(($N$10-$X$10)/10)) -> #REF! | X10: =1.05*$X$21 -> #REF! | AG10: Decrescita | AH10: =(AH11-AH9)/10 -> 0.0052978384 | AJ10: =AH11-$AH$10 -> 0.067680545 | AK10: =AJ10-$AH$10 -> 0.062382707 | AL10: =AK10-$AH$10 -> 0.057084869 | AM10: =AL10-$AH$10 -> 0.05178703 | AN10: =AM10-$AH$10 -> 0.046489192 | AO10: =AN10-$AH$10 -> 0.041191353 | AP10: =AO10-$AH$10 -> 0.035893515 | AQ10: =AP10-$AH$10 -> 0.030595677 | AR10: =AQ10-$AH$10 -> 0.025297838 | AS10: =AR10-$AH$10 -> 0.02
D11: FCF | E11: =SUM(E9:E10) -> 1954684.4 | F11: =SUM(F9:F10) -> 2982382.7 | G11: =SUM(G9:G10) -> 2814 | H11: =SUM(H9:H10) -> 2829848.3 | I11: =SUM(I9:I10) -> -1633643.5 | J11: =SUM(J9:J10) -> -252618.51 | K11: =SUM(K9:K10) -> 964912.38 | L11: =SUM(L9:L10) -> 901656.22 | ... N11: =SUM(N9:N10) -> 827516.85 | O11: =M11*(1+O12) -> 976799.5 | P11: =O11*(1+P12) -> 1037734.9 | Q11: =P11*(1+Q12) -> 1096973.9 | R11: =Q11*(1+R12) -> 1153782.9 | S11: =R11*(1+S12) -> 1207421.3 | T11: =S11*(1+T12) -> 1257156.6 | U11: =T11*(1+U12) -> 1302280.4 | V11: =U11*(1+V12) -> 1342124.5 | W11: =V11*(1+W12) -> 1376077.4 | X11: =W11*(1+X12) -> 1403598.9 | AG11: Start | AH11: =N8 -> 0.072978384
D12: Adjusted Free cash flow | I12: =I11+CAPEX!AV112 -> -1259643.5 | J12: =J11+CAPEX!AW112 -> 845381.49 | K12: =K11+CAPEX!AX112 -> 1412912.4 | L12: =L11+CAPEX!AY112 -> 1641656.2 | M12: =M11+CAPEX!AZ112 -> 1664879.9 | N12: =N11+CAPEX!BA112 -> 1847516.9 | O12: =AJ10 -> 0.067680545 | P12: =AK10 -> 0.062382707 | Q12: =AL10 -> 0.057084869 | R12: =AM10 -> 0.05178703 | S12: =AN10 -> 0.046489192 | T12: =AO10 -> 0.041191353 | U12: =AP10 -> 0.035893515 | V12: =AQ10 -> 0.030595677 | ... X12: =AS10 -> 0.02 | Y12: =X11*(1+AB6)/(AB7-AB6) -> 18912430
D13: Financing Flow | I13: =1.0957^(I3-2021) -> 1.0957 | J13: =1.0957^(J3-2021) -> 1.2005585 | K13: =1.0957^(K3-2021) -> 1.3154519 | L13: =1.0957^(L3-2021) -> 1.4413407 | M13: =1.0957^(M3-2021) -> 1.579277 | N13: =1.0957^(N3-2021) -> 1.7304138 | O13: =1.0957^(O3-2021) -> 1.8960144 | P13: =1.0957^(P3-2021) -> 2.077463 | ... X13: =1.0957^(X3-2021) -> 4.3158524
D14: Δcash | G14: 4425087.3 | I14: =I11/I13 -> -1490958.8 | J14: =J11/J13 -> -210417.5 | K14: =K11/K13 -> 733521.58 | L14: =L11/L13 -> 625567.73 | M14: =M11/M13 -> 579303.02 | N14: =N11/N13 -> 478219.05 | O14: =O11/O13 -> 515185.7 | P14: =P11/P13 -> 499520.28 | ... X14: =X11/X13 -> 325219.4 | Y14: =Y12/X13 -> 4382084.4 | AA14: =Z24 -> 10142573 | AB14: 0.0917 | AC14: 0.0937 | AD14: 0.0957 | AE14: =AD14+0.002 -> 0.0977 | AF14: =AE14+0.002 -> 0.0997 | AG14: =AF14+0.002 -> 0.1017 | AH14: =AG14+0.002 -> 0.1037
N15: =M11/(0.1-0.02) -> 11435999 | AA15: 0.014
D16: Enterprise Value | E16: =I16*1.0957^(10.5/12) -> 10142573 | H16: =Y14/I16 -> 0.46801827 | I16: =SUM(I14:Y14) -> 9363062.8 | J16: =SUM(I14:N14)+(M11/(0.096-0.03))/N13 -> 8725930.1 | N16: =N15/N13 -> 6608823.3 | O16: =N5/M5-1 -> 0.14369526 | P16: =P11/O11-1 -> 0.062382707 | Q16: =Q11/P11-1 -> 0.057084869 | R16: =R11/Q11-1 -> 0.05178703 | S16: =S11/R11-1 -> 0.046489192 | AA16: 0.016
D17: (+) Net Debt (Financial liab. - Cash & equivalents) | E17: =H17 -> -4135760.7 | G17: (-) Net Debt | H17: =-Sch_Deb!P80 -> -4135760.7 | K17: =K5/J5-1 -> 0.65670381 | L17: =L5/K5-1 -> 0.041096847 | M17: =M5/L5-1 -> -0.0417154 | N17: =N5/M5-1 -> 0.14369526 | AA17: 0.018
D18: (-) Other Financial assets (current and non-current) | E18: -175714 | G18: (-) Other Debt-like Items / Employee benefits | H18: -56.862 | I18: 589994732307 | J18: =J11/I11-1 -> -0.84536497 | K18: =K11/J11-1 -> -4.8196424 | L18: =L11/K11-1 -> -0.065556376 | M18: =M11/L11-1 -> 0.014666017 | N18: =N11/M11-1 -> -0.095491305 | AA18: 0.02
D19: (+) Other debt-like items (Employee benefits) | E19: 56862 | G19: (+) Other Financial Assets | H19: 175,714,000 | M19: Amm.to | N19: ='Pro_Forma IS'!M13 -> -1424148.7 | AA19: 0.022
D20: (+) Minority Interests | E20: -13377 | G20: (-) Minority Interests | H20: 13.377 | M20: coeff. Amm.to | N20: =-N19/SUM('Pro_Forma BS'!M63:M65) -> 0.11751977 | AA20: 0.024
D21: (-) Investments in associates | E21: 0 | G21: (+) Investments in Associates | H21: 0 | M21: D&A | O21: =($N$19+$N$20*N10) -> -1644214.2 | P21: =($N$19+$N$20*O10) -> #REF! | Q21: =($N$19+$N$20*P10) -> #REF! | R21: =($N$19+$N$20*Q10) -> #REF! | S21: =($N$19+$N$20*R10) -> #REF! | T21: =($N$19+$N$20*S10) -> #REF! | U21: =($N$19+$N$20*T10) -> #REF! | V21: =($N$19+$N$20*U10) -> #REF! | ... X21: =($N$19+$N$20*W10) -> #REF! | AA21: 0.026
D22: (+) Surplus assets | E22: 13567 | J22: =J9/I9-1 -> -5.2285111 | K22: =K9/J9-1 -> 0.33488257 | L22: =L9/K9-1 -> 0.096988356 | M22: =M9/L9-1 -> 0.0095492808 | N22: =N9/M9-1 -> 0.072978384
D23: Equity Value Implied | E23: =E16+SUM(E17:E22) -> 5888150.2
D24: Prezzo per share | E24: =E23*10^3/I18 -> 0.0099800047 | Q24: EV/EBTDA | R24: =10.64 -> 10.64 | Z24: =(I11/(1+AB7)^1+J11/(1+AB7)^2+K11/(1+AB7)^3+L11/(1+AB7)^4+M11/(1+AB7)^5+N11/(1+AB7)^6+O11/(1+AB7)^7+P11/(1+AB7)^8+Q11/(1+AB7)^9+R11/(1+AB7)^10+S11/(1+AB7)^11+T11/(1+AB7)^12+U11/(1+AB7)^13+V11/(1+AB7)^14+W11/(1+AB7)^15+X11/(1+AB7)^16+((X11*(1+AB6))/(AB7-AB6)/(1+AB7)^16))*(1+AB7)^(10.5/12) -> 10142573
I25: -1399 | J25: -205 | K25: 664 | L25: 917 | M25: 1080 | N25: 785 | O25: =M25/(0.1-0.02) -> 13500 | R25: =R24*N5 -> 32559371 | Z25: =I11/(1+E35)^I35+J11/(1+E35)^J35+K11/(1+E35)^K35+L11/(1+E35)^L35+M11/(1+E35)^M35+N11/(1+E35)^N35+O11/(1+E35)^O35+P11/(1+E35)^P35+Q11/(1+E35)^Q35+R11/(1+E35)^R35+S11/(1+E35)^S35+T11/(1+E35)^T35+U11/(1+E35)^U35+V11/(1+E35)^V35+W11/(1+E35)^W35+X11/(1+E35)^X35+(X11*(1+E34)/((E35-E34)*(1+E35)^X35)) -> #DIV/0!
D26: Market cap | E26: =3473888983824 -> 3473888983824 | H26: =SUM(I26:O26) -> 8418.0618 | I26: =I25/(1.1^(I3-2021)) -> -1271.8182 | J26: =J25/(1.1^(J3-2021)) -> -169.42149 | K26: =K25/(1.1^(K3-2021)) -> 498.87303 | L26: =L25/(1.1^(L3-2021)) -> 626.32334 | M26: =M25/(1.1^(M3-2021)) -> 670.59503 | N26: =N25/(1.1^(N3-2021)) -> 443.11204 | O26: =O25/(1.1^(N3-2021)) -> 7620.3981 | R26: =R25/N13 -> 18815945
D27: CamBio pesos USD | E27: 0.0010531189 | R27: =SUM(I14:N14)+R26 -> 19531180 | S27: =1.0982^(11/12)*R27 -> 21282361
D28: Market Cap USD | E28: =E27*E26 -> 3.6584181e+09
E29: =E28/I18 -> 0.0062007641 | J29: =J10/I10-1 -> 0.58790032 | K29: =K10/J10-1 -> -0.33122207 | L29: =L10/K10-1 -> 0.21695693 | M29: =M10/L10-1 -> 0.0066494974 | N29: =N10/M10-1 -> 0.16921472
E30: =E24/E29 -> 1.6094798
G32: 4791086312

Sheet Real GDP Brazil
A1: FRED Graph Observations
A2: Federal Reserve Economic Data | D2: Mean quarterly Growth | E2: =AVERAGE(C14:C118) -> 0.0061714214
A3: Link: https://fred.stlouisfed.org | F3: {=#REF!} -> #REF! | G3: =E2 -> 0.0061714214
A4: Help: https://fredhelp.stlouisfed.org
A5: Economic Research Division | D5: Mean quarterly Growth Last Years, no COVID | E5: =AVERAGE(C81:C108) -> 0.00011813035
A6: Federal Reserve Bank of St. Louis
A9: NGDPRNSAXDCBRQ | B9: Real Gross Domestic Product for Brazil, Domestic Currency, Quarterly, Not Seasonally Adjusted
A11: Frequency: Quarterly
A12: observation_date | B12: NGDPRNSAXDCBRQ | C12: Growth
A13: 35065 | B13: 170920
A14: 35156 | B14: 176708.7 | C14: =B14/B13-1 -> 0.033867891
A15: 35247 | B15: 189844.3 | C15: =B15/B14-1 -> 0.074334767
A16: 35339 | B16: 184112.9 | C16: =B16/B15-1 -> -0.030190003
A17: 35431 | B17: 176732.3 | C17: =B17/B16-1 -> -0.040087359
A18: 35521 | B18: 185109.5 | C18: =B18/B17-1 -> 0.047400503
A19: 35612 | B19: 193244.9 | C19: =B19/B18-1 -> 0.043949122
A20: 35704 | B20: 190996 | C20: =B20/B19-1 -> -0.011637565
A21: 35796 | B21: 178513 | C21: =B21/B20-1 -> -0.06535739
A22: 35886 | B22: 187904 | C22: =B22/B21-1 -> 0.052606813
A23: 35977 | B23: 193932.1 | C23: =B23/B22-1 -> 0.032080743
A24: 36069 | B24: 188256.1 | C24: =B24/B23-1 -> -0.029267976
A25: 36161 | B25: 179883.3 | C25: =B25/B24-1 -> -0.044475584
... A118: 44652 | B118: 310255.1 | C118: =B118/B117-1 -> 0.022625274
B121: =SUM(B114:B117)/SUM(B110:B113)-1 -> 0.047119757
C122: =1.83/1.75-1 -> 0.045714286

Sheet Regression_Brazil 
A1: Date | B1: RPK | C1: GDP | D1: Jet Fuel Price dollar per Gallon | E1: Ln(RPK) | F1: LN(GDP) | G1: LN(fuel) | H1: LN(jet Fuel_t-1)
A2: 36526 | B2: 6331103905 | C2: 187799.5 | D2: 0.77733333 | E2: =LN(B2) -> 22.56874 | F2: =LN(C2) -> 12.14313 | G2: =LN('Real GDP Brazil'!B29) -> 12.14313 | H2: =LN(0.652333333) -> -0.4271996
A3: 36617 | B3: 5853651051 | C3: 194596.6 | D3: 0.75533333 | E3: =LN(B3) -> 22.490331 | F3: =LN(C3) -> 12.178684 | G3: =F3 -> 12.178684 | H3: -0.25188602
A4: 36708 | B4: 6527334337 | C4: 201534.7 | D4: 0.90433333 | E4: =LN(B4) -> 22.599264 | F4: =LN(C4) -> 12.213717 | G4: =F4 -> 12.213717 | H4: -0.28059613
A5: 36800 | B5: 6507878786 | C5: 201179.5 | D5: 0.95766667 | E5: =LN(B5) -> 22.596279 | F5: =LN(C5) -> 12.211953 | G5: =F5 -> 12.211953 | H5: -0.10055726
A6: 36892 | B6: 6474253999 | C6: 194325.7 | D6: 0.811 | E6: =LN(B6) -> 22.591099 | F6: =LN(C6) -> 12.177291 | G6: =F6 -> 12.177291 | H6: -0.043255508
A7: 36982 | B7: 6078702660 | C7: 199123 | D7: 0.786 | E7: =LN(B7) -> 22.528057 | F7: =LN(C7) -> 12.201678 | G7: =F7 -> 12.201678 | H7: -0.20948722
A8: 37073 | B8: 6746361477 | C8: 202464.1 | D8: 0.73766667 | E8: =LN(B8) -> 22.632269 | F8: =LN(C8) -> 12.218318 | G8: =F8 -> 12.218318 | H8: -0.24079849
A9: 37165 | B9: 6800534625 | C9: 200109.7 | D9: 0.56 | E9: =LN(B9) -> 22.640267 | F9: =LN(C9) -> 12.206621 | G9: =F9 -> 12.206621 | H9: -0.30426323
A10: 37257 | B10: 6845593446 | C10: 195252.5 | D10: 0.57133333 | E10: =LN(B10) -> 22.646871 | F10: =LN(C10) -> 12.182049 | G10: =F10 -> 12.182049 | H10: -0.5798185
A11: 37347 | B11: 6548776431 | C11: 203699.3 | D11: 0.66266667 | E11: =LN(B11) -> 22.602544 | F11: =LN(C11) -> 12.2244 | G11: =F11 -> 12.2244 | H11: -0.55978247
A12: 37438 | B12: 7124301197 | C12: 210916.4 | D12: 0.73766667 | E12: =LN(B12) -> 22.686777 | F12: =LN(C12) -> 12.259217 | G12: =F12 -> 12.259217 | H12: -0.41148318
A13: 37530 | B13: 6185844970 | C13: 210460.6 | D13: 0.76966667 | E13: =LN(B13) -> 22.545529 | F13: =LN(C13) -> 12.257054 | G13: =F13 -> 12.257054 | H13: -0.30426323
A14: 37622 | B14: 6726270399 | C14: 200459.9 | D14: 0.945 | E14: =LN(B14) -> 22.629287 | F14: =LN(C14) -> 12.20837 | G14: =F14 -> 12.20837 | H14: -0.26179776
... A81: 43739 | B81: 25572691851 | C81: 303031.7 | D81: 1.8593333 | E81: =LN(B81) -> 23.964791 | F81: =LN(C81) -> 12.621593 | G81: =F81 -> 12.621593 | H81: 0.62183018
A86: OUTPUT RIEPILOGO
A88: Statistica della regressione
A89: R multiplo | B89: 0.98152573
A90: R al quadrato | B90: 0.96339276
A91: R al quadrato corretto | B91: 0.96244192
A92: Errore standard | B92: 0.1005452
A93: Osservazioni | B93: 80
A95: ANALISI VARIANZA
B96: gdl | C96: SQ | D96: MQ | E96: F | F96: Significatività F
A97: Regressione | B97: 2 | C97: 20.485655 | D97: 10.242827 | E97: 1013.2046 | F97: 4.9811367e-56
A98: Residuo | B98: 77 | C98: 0.77841903 | D98: 0.010109338
A99: Totale | B99: 79 | C99: 21.264074
B101: Coefficienti | C101: Errore standard | D101: Stat t | E101: Valore di significatività | F101: Inferiore 95% | G101: Superiore 95% | H101: Inferiore 95,0% | I101: Superiore 95,0%
A102: Intercetta | B102: -21.711508 | C102: 1.414966 | D102: -15.344191 | E102: 3.9636961e-25 | F102: -24.529065 | G102: -18.89395 | H102: -24.529065 | I102: -18.89395
A103: Variabile X 1 | B103: 3.6233619 | C103: 0.11466777 | D103: 31.598783 | E103: 7.6939211e-46 | F103: 3.3950292 | G103: 3.8516946 | H103: 3.3950292 | I103: 3.8516946
A104: Variabile X 2 | B104: -0.19331577 | C104: 0.036856503 | D104: -5.2450925 | E104: 1.3336017e-06 | F104: -0.26670644 | G104: -0.11992509 | H104: -0.26670644 | I104: -0.11992509
A108: OUTPUT RESIDUI
A110: Osservazione | B110: Y prevista | C110: Residui | D110: Residui standard
A111: 1 | B111: 22.370033 | C111: 0.19870789 | D111: 2.0018058
A112: 2 | B112: 22.464966 | C112: 0.025365475 | D112: 0.25553467
A113: 3 | B113: 22.597453 | C113: 0.0018116301 | D113: 0.018250567
A114: 4 | B114: 22.556257 | C114: 0.040022626 | D114: 0.40319246
A115: 5 | B115: 22.419587 | C115: 0.17151249 | D115: 1.7278362
A116: 6 | B116: 22.540085 | C116: -0.012028132 | D116: -0.12117276
A117: 7 | B117: 22.60643 | C117: 0.025838687 | D117: 0.26030186
...

Sheet Domestic, Brazil estimate
C1: {=TRANSPOSE('A1-jet Fuel'!C105:D107)} -> q2-2021 | D1: q3-2021 | E1: q4-2021 | F1: Q1-2022 | G1: q2-2022 | H1: q3-2022 | I1: q4-2022 | J1: q1-2023 | K1: q2-2023 | L1: q3-2023 | M1: q4-2023 | N1: q1-2024 | O1: q2-2024 | P1: q3-2024 | Q1: q4-2024 | R1: q1-2025 | S1: q2-2025 | T1: q3-2025 | U1: q4-2025 | V1: q1-2026 | W1: q2-2026 | X1: q3-2026 | Y1: q4-2026 | Z1: q1-2027 | AA1: q2-2027 | AB1: q3-2027 | AC1: q4-2027 | AD1: q1-2028 | AE1: q2-2028 | AF1: q3-2028 | AG1: q4-2028
A2: JET FUEL | B2: USD/gal | C2: 1.7593333 | D2: 1.9023333 | E2: 2.1946667 | F2: ='Forecast Drivers'!H10 -> 3.43 | G2: =F2 -> 3.43 | H2: =G2 -> 3.43 | I2: =4*'Forecast Drivers'!H10-SUM('Domestic, Brazil estimate'!F2:H2) -> 3.43 | J2: ='Forecast Drivers'!I10 -> 3.1 | K2: =J2 -> 3.1 | L2: =K2 -> 3.1 | M2: =L2 -> 3.1 | N2: ='Forecast Drivers'!J10 -> 2.38 | O2: =N2 -> 2.38 | P2: =O2 -> 2.38 | Q2: =P2 -> 2.38 | R2: ='Forecast Drivers'!K10 -> 2.38 | S2: =R2 -> 2.38 | T2: =S2 -> 2.38 | U2: =T2 -> 2.38 | V2: ='Forecast Drivers'!L10 -> 2.38 | W2: =V2 -> 2.38 | X2: =W2 -> 2.38 | Y2: =X2 -> 2.38 | Z2: ='Forecast Drivers'!M10 -> 2.38 | AA2: =Z2 -> 2.38 | AB2: =AA2 -> 2.38 | AC2: =AB2 -> 2.38 | AD2: =AC2 -> 2.38 | AE2: =AD2 -> 2.38 | AF2: =AE2 -> 2.38 | AG2: =AF2 -> 2.38
A3: LN(Jet fuel) | C3: =LN(C2) -> 0.56493495 | D3: =LN(D2) -> 0.6430812 | E3: =LN(E2) -> 0.78603017 | F3: =LN(F2) -> 1.2325603 | G3: =LN(G2) -> 1.2325603 | H3: =LN(H2) -> 1.2325603 | I3: =LN(I2) -> 1.2325603 | J3: =LN(J2) -> 1.1314021 | ... AG3: =LN(AG2) -> 0.86710049
A5: GDP Brasil | E5: ='Real GDP Brazil'!B118 -> 310255.1 | F5: =E5*(1+'Forecast Drivers'!$H$9/4) -> 311030.74 | G5: =F5*(1+'Forecast Drivers'!$H$9/4) -> 311808.31 | H5: =G5*(1+'Forecast Drivers'!$H$9/4) -> 312587.84 | I5: =H5*(1+'Forecast Drivers'!$H$9/4) -> 313369.3 | J5: =I5*(1+'Forecast Drivers'!$I$9/4) -> 314152.73 | K5: =J5*(1+'Forecast Drivers'!$I$9/4) -> 314938.11 | L5: =K5*(1+'Forecast Drivers'!$I$9/4) -> 315725.46 | M5: =L5*(1+'Forecast Drivers'!$I$9/4) -> 316514.77 | N5: =M5*(1+'Forecast Drivers'!$J$9/4) -> 317306.06 | O5: =N5*(1+'Forecast Drivers'!$J$9/4) -> 318099.32 | P5: =O5*(1+'Forecast Drivers'!$J$9/4) -> 318894.57 | Q5: =P5*(1+'Forecast Drivers'!$J$9/4) -> 319691.81 | R5: =Q5*(1+'Forecast Drivers'!$K$9/4) -> 320491.04 | S5: =R5*(1+'Forecast Drivers'!$K$9/4) -> 321292.26 | T5: =S5*(1+'Forecast Drivers'!$K$9/4) -> 322095.49 | U5: =T5*(1+'Forecast Drivers'!$K$9/4) -> 322900.73 | V5: =U5*(1+'Forecast Drivers'!$L$9/4) -> 323707.98 | W5: =V5*(1+'Forecast Drivers'!$L$9/4) -> 324517.25 | X5: =W5*(1+'Forecast Drivers'!$L$9/4) -> 325328.55 | Y5: =X5*(1+'Forecast Drivers'!$L$9/4) -> 326141.87 | Z5: =Y5*(1+'Forecast Drivers'!$M$9/4) -> 326957.22 | AA5: =Z5*(1+'Forecast Drivers'!$M$9/4) -> 327774.62 | AB5: =AA5*(1+'Forecast Drivers'!$M$9/4) -> 328594.05 | AC5: =AB5*(1+'Forecast Drivers'!$M$9/4) -> 329415.54 | AD5: =AC5*(1+'Forecast Drivers'!$M$9/4) -> 330239.08 | AE5: =AD5*(1+'Forecast Drivers'!$M$9/4) -> 331064.67 | AF5: =AE5*(1+'Forecast Drivers'!$M$9/4) -> 331892.34 | AG5: =AF5*(1+'Forecast Drivers'!$M$9/4) -> 332722.07
A6: Ln(Brasil) | E6: =LN(E5) -> 12.64515 | F6: =LN(F5) -> 12.647647 | G6: =LN(G5) -> 12.650144 | H6: =LN(H5) -> 12.652641 | I6: =LN(I5) -> 12.655138 | J6: =LN(J5) -> 12.657635 | K6: =LN(K5) -> 12.660131 | L6: =LN(L5) -> 12.662628 | ... AG6: =LN(AG5) -> 12.715063
A8: Forecast of ln(RPKS) | F8: ='Regression_Brazil '!$B$102+E6*'Regression_Brazil '!$B$103+'Domestic, Brazil estimate'!E3*'Regression_Brazil '!$B$104 -> 23.954496 | G8: ='Regression_Brazil '!$B$102+F6*'Regression_Brazil '!$B$103+'Domestic, Brazil estimate'!F3*'Regression_Brazil '!$B$104 -> 23.877222 | H8: ='Regression_Brazil '!$B$102+G6*'Regression_Brazil '!$B$103+'Domestic, Brazil estimate'!G3*'Regression_Brazil '!$B$104 -> 23.886269 | I8: ='Regression_Brazil '!$B$102+H6*'Regression_Brazil '!$B$103+'Domestic, Brazil estimate'!H3*'Regression_Brazil '!$B$104 -> 23.895316 | J8: ='Regression_Brazil '!$B$102+I6*'Regression_Brazil '!$B$103+'Domestic, Brazil estimate'!I3*'Regression_Brazil '!$B$104 -> 23.904363 | K8: ='Regression_Brazil '!$B$102+J6*'Regression_Brazil '!$B$103+'Domestic, Brazil estimate'!J3*'Regression_Brazil '!$B$104 -> 23.932966 | L8: ='Regression_Brazil '!$B$102+K6*'Regression_Brazil '!$B$103+'Domestic, Brazil estimate'!K3*'Regression_Brazil '!$B$104 -> 23.942013 | M8: ='Regression_Brazil '!$B$102+L6*'Regression_Brazil '!$B$103+'Domestic, Brazil estimate'!L3*'Regression_Brazil '!$B$104 -> 23.95106 | ... AG8: ='Regression_Brazil '!$B$102+AF6*'Regression_Brazil '!$B$103+'Domestic, Brazil estimate'!AF3*'Regression_Brazil '!$B$104 -> 24.183096
A9: RPKs Forecasted | F9: =EXP(F8) -> 2.5310777e+10 | G9: =EXP(G8) -> 2.3428567e+10 | H9: =EXP(H8) -> 2.3641489e+10 | I9: =EXP(I8) -> 2.3856346e+10 | J9: =EXP(J8) -> 2.4073156e+10 | K9: =EXP(K8) -> 2.4771652e+10 | L9: =EXP(L8) -> 2.4996781e+10 | M9: =EXP(M8) -> 2.5223955e+10 | ... AG9: =EXP(AG8) -> 3.1811563e+10
B10: 2019 | C10: =B20 -> 96449372986
A11: Quarterly sum | B11: 2020 | I11: =SUM(F9:I9) -> 9.6237179e+10 | M11: =SUM(J9:M9) -> 9.9065545e+10 | Q11: =SUM(N9:Q9) -> 1.0728522e+11 | U11: =SUM(R9:U9) -> 1.1262227e+11 | Y11: =SUM(V9:Y9) -> 1.1677253e+11 | AC11: =SUM(Z9:AC9) -> 1.2107574e+11 | AG11: =SUM(AD9:AG9) -> 1.2553752e+11
B12: 2021
A13: Forecasted annual series | B13: 2022 | C13: =I11 -> 9.6237179e+10
B14: 2023 | C14: =M11 -> 9.9065545e+10
B15: 2024 | C15: =Q11 -> 1.0728522e+11
B16: 2025 | C16: =U11 -> 1.1262227e+11
B17: 2026 | C17: =Y11 -> 1.1677253e+11
B18: 2027 | C18: =AC11 -> 1.2107574e+11
A19: Estimate | B19: 2028 | C19: =AG11 -> 1.2553752e+11
A20: 2019 RPks | B20: =B53 -> 96449372986
A22: 5 Years Implied CAGR | B22: =(C18/C13)^(1/5)-1 -> 0.04699076
A23: 8 Years GAGR | B23: =(C19/C10)^(1/8)-1 -> 0.033497113
A33: YEAR | B33: RPKs
A34: 2000 | B34: 25219968079
A35: 2001 | B35: 27336355492
A36: 2002 | B36: 26704516044
A37: 2003 | B37: 26099852761
A38: 2004 | B38: 28881235043
A39: 2005 | B39: 35252145026
A40: 2006 | B40: 40441366277
A41: 2007 | B41: 45470884457
A42: 2008 | B42: 49046278775
A43: 2009 | B43: 57194653909
A44: 2010 | B44: 69862011045
A45: 2011 | B45: 81103599006
... A53: 2019 | B53: 96449372986
A54: 2020 | B54: =48695532564 -> 48695532564
A55: 2021 | B55: 66373162099
A56: =B13 -> 2022 | B56: =C13 -> 9.6237179e+10
A57: =B14 -> 2023 | B57: =C14 -> 9.9065545e+10
A58: =B15 -> 2024 | B58: =C15 -> 1.0728522e+11
A59: =B16 -> 2025 | B59: =C16 -> 1.1262227e+11
...

Sheet Bra_Mkt_Sh
A2: Brazil Domesstic Market
B3: RPK Brazil mil | C3: historical | D3: historical | E3: historical | F3: historical | G3: historical | H3: historical | I3: historical | J3: historical | K3: historical | L3: historical | M3: expected | N3: forecast | O3: forecast | P3: forecast | Q3: forecast | R3: forecast
B4: Ano | C4: 2012 | D4: 2013 | E4: 2014 | F4: 2015 | G4: 2016 | H4: =G4+1 -> 2017 | I4: =H4+1 -> 2018 | J4: =I4+1 -> 2019 | K4: =J4+1 -> 2020 | L4: =K4+1 -> 2021 | M4: =L4+1 -> 2022 | N4: =M4+1 -> 2023 | O4: =N4+1 -> 2024 | ... R4: =Q4+1 -> 2027
B5: Domestica | C5: 86771900 | D5: 87739855 | E5: 93183427 | F5: 94279579 | G5: 88893631 | H5: 91857638 | I5: 95870487 | J5: 96449373 | K5: 48695533 | L5: 66373162 | M5: ='Domestic, Brazil estimate'!B56/1000 -> 96237179 | N5: ='Domestic, Brazil estimate'!B57/1000 -> 99065545 | O5: ='Domestic, Brazil estimate'!B58/1000 -> 1.0728522e+08 | P5: ='Domestic, Brazil estimate'!B59/1000 -> 1.1262227e+08 | Q5: ='Domestic, Brazil estimate'!B60/1000 -> 1.1677253e+08 | R5: ='Domestic, Brazil estimate'!B61/1000 -> 1.2107574e+08 | T5: input
B6: rate g | D6: =D5/C5-1 -> 0.011155171 | E6: =E5/D5-1 -> 0.062042177 | F6: =F5/E5-1 -> 0.011763384 | G6: =G5/F5-1 -> -0.057127407 | H6: =H5/G5-1 -> 0.033343296 | I6: =I5/H5-1 -> 0.043685521 | J6: =J5/I5-1 -> 0.006038211 | K6: =K5/J5-1 -> -0.4951182 | ... R6: =R5/Q5-1 -> 0.036851174
B7: growth | D7: =D5-C5 -> 967955.37 | E7: =E5-D5 -> 5443571.6 | F7: =F5-E5 -> 1096152.5 | G7: =G5-F5 -> -5385947.9 | H7: =H5-G5 -> 2964006.6 | I7: =I5-H5 -> 4012848.8 | J7: =J5-I5 -> 578886.23 | K7: =K5-J5 -> -47753840 | ... R7: =R5-Q5 -> 4303204.9
A10: GOL | B10: RPK mil | C10: 29266253 | D10: 30922480 | E10: 33661475 | F10: 33833189 | G10: 31999872 | H10: 33219792 | I10: 34258111 | J10: 36429290 | K10: 18838943 | L10: 22114929 | M10: =0.345377057469976*M5 -> 33238114 | N10: =M10+N11 -> 34072190 | O10: =N10+O11 -> 36447134 | P10: =O10+P11 -> 37957366 | Q10: =P10+Q11 -> 39131772 | R10: =Q10+R11 -> 40349455
B11: gorwth | D11: =D10-C10 -> 1656227 | E11: =E10-D10 -> 2738995 | F11: =F10-E10 -> 171714 | G11: =G10-F10 -> -1833317 | H11: =H10-G10 -> 1219920 | I11: =I10-H10 -> 1038319 | J11: =J10-I10 -> 2171179 | K11: =K10-J10 -> -17590347 | ... M11: =M10-L10 -> 11123185 | N11: =N14*N7 -> 834076.12 | O11: =O14*O7 -> 2374944.6 | P11: =P14*P7 -> 1510231.9 | Q11: =Q14*Q7 -> 1174405.1 | R11: =R14*R7 -> 1217683.3
B12: growth share | D12: =D11/D7 -> 1.7110572 | E12: =E11/E7 -> 0.50316138 | F12: =F11/F7 -> 0.15665156 | G12: =G11/G7 -> 0.34038892 | H12: =H11/H7 -> 0.41157803 | I12: =I11/I7 -> 0.2587486 | J12: =J11/J7 -> 3.7506144 | K12: =K11/K7 -> 0.3683546 | L12: =L11/L7 -> 0.18531817 | M12: =M11/$M$7 -> 0.3724611
B13: relative growth share | D13: =D12/(D12+D18+D30) -> 0.39005666 | E13: =E12/(E12+E18+E30) -> 0.36955147 | F13: =F12/(F12+F18+F30) -> -0.71098101 | G13: =G12/(G12+G18+G30) -> 0.28508009 | H13: =H12/(H12+H18+H30) -> 0.80898322 | I13: =I12/(I12+I18+I30) -> 0.33198767 | J13: =J12/(J12+J18+J30) -> 0.22052615 | K13: =K12/(K12+K18+K30) -> 0.39955071 | ... M13: =M12/(M12+M18+M30) -> 0.36851417
B14: avg relative growth share | M14: =SUMPRODUCT(D13:M13,$D$54:$M$54) -> 0.29814058 | N14: =$M14*(1-N$44-$N$36) -> 0.29489689 | O14: =$M14*(1-O$44-$N$36) -> 0.28893408 | P14: =$M14*(1-P$44-$N$36) -> 0.28297127 | Q14: =$M14*(1-Q$44-$N$36) -> 0.28297127 | R14: =$M14*(1-R$44-$N$36) -> 0.28297127
A16: AZUL | B16: RPK mil | C16: 8684707 | D16: 11420585 | E16: 15438446 | F16: 15992755 | G16: 15089537 | H16: 16364798 | I16: 17808150 | J16: 22588609 | K16: 13814405 | L16: 23303714 | M16: =0.31009361875521*M5 -> 29842535 | N16: =M16+N17 -> 30615691 | O16: =N16+O17 -> 32817172 | P16: =O16+P17 -> 34217098 | Q16: =P16+Q17 -> 35305725 | R16: =Q16+R17 -> 36434470
B17: growth | D17: =D16-C16 -> 2735878 | E17: =E16-D16 -> 4017861 | F17: =F16-E16 -> 554309 | G17: =G16-F16 -> -903218 | H17: =H16-G16 -> 1275261 | I17: =I16-H16 -> 1443352 | J17: =J16-I16 -> 4780459 | K17: =K16-J16 -> -8774204 | ... M17: =M16-L16 -> 6538821.2 | N17: =N20*N7 -> 773155.92 | O17: =O20*O7 -> 2201480.7 | P17: =P20*P7 -> 1399925.9 | Q17: =Q20*Q7 -> 1088627.6 | R17: =R20*R7 -> 1128744.8
B18: growth share | D18: =D17/D7 -> 2.8264506 | E18: =E17/E7 -> 0.7380928 | F18: =F17/F7 -> 0.50568604 | G18: =G17/G7 -> 0.16769899 | H18: =H17/H7 -> 0.43024904 | I18: =I17/I7 -> 0.35968263 | J18: =J17/J7 -> 8.2580286 | K18: =K17/K7 -> 0.18373819 | L18: =L17/L7 -> 0.53679759 | M18: =M17/$M$7 -> 0.21895317
B19: relative growht share | D19: =D18/(D12+D18+D30) -> 0.64432438 | E19: =E18/(E12+E18+E30) -> 0.54209899 | F19: =F18/(F12+F18+F30) -> -2.2951138 | G19: =G18/(G12+G18+G30) -> 0.14045005 | H19: =H18/(H12+H18+H30) -> 0.8456823 | I19: =I18/(I12+I18+I30) -> 0.46149119 | J19: =J18/(J12+J18+J30) -> 0.48555013 | K19: =K18/(K12+K18+K30) -> 0.19929905 | ... M19: =M18/(M12+M18+M30) -> 0.21663295
B20: avg relative growth share | M20: =SUMPRODUCT(D19:M19,$D$54:$M$54) -> 0.27636465 | N20: =$M20*(1-N$44-$N$36) -> 0.27335788 | O20: =$M20*(1-O$44-$N$36) -> 0.26783058 | P20: =$M20*(1-P$44-$N$36) -> 0.26230329 | Q20: =$M20*(1-Q$44-$N$36) -> 0.26230329 | R20: =$M20*(1-R$44-$N$36) -> 0.26230329
